2021-03-15 11:06:33	INFO	::casa	
2021-03-15 11:06:33	INFO	::casa	CASA Version MODULAR 6.2.0.103
2021-03-15 11:06:33	INFO	::casa	Can't import casatelemetry module.
2021-03-15 11:06:33	INFO	exportuvfits::::casa	##########################################
2021-03-15 11:06:33	INFO	exportuvfits::::casa	##### Begin Task: exportuvfits       #####
2021-03-15 11:06:33	INFO	exportuvfits::::casa	exportuvfits( vis='/Users/Ridhima/Softwares/anaconda3/lib/python3.6/site-packages/dfilter_imaging-1.1.0-py3.6.egg/dfilter_imaging/data/zen.2458114.31193.HH.xx.t0.ms', fitsfile='/Users/Ridhima/Softwares/anaconda3/lib/python3.6/site-packages/dfilter_imaging-1.1.0-py3.6.egg/dfilter_imaging/data/zen.2458114.31193.HH.xx.t0.uvfits', datacolumn='corrected', field='', spw='', antenna='', timerange='', writesyscal=False, multisource=True, combinespw=True, writestation=True, padwithflags=False, overwrite=False )
2021-03-15 11:06:33	INFO	exportuvfits::MSFitsOutput::write	 nchan=1024 startchan=0 stepchan=1 avgchan=1
2021-03-15 11:06:33	SEVERE	exportuvfits::ms::tofits	Exception Reported: Exception: Error in output file : File /Users/Ridhima/Softwares/anaconda3/lib/python3.6/site-packages/dfilter_imaging-1.1.0-py3.6.egg/dfilter_imaging/data/zen.2458114.31193.HH.xx.t0.uvfits exists, and the user does not want to remove it..
2021-03-15 11:06:33	SEVERE	exportuvfits::ms::tofits+	... thrown by void casa6core::MSFitsOutput::write() const at File: casacore/msfits/MSFits/MSFitsOutput.cc, line: 173
2021-03-15 11:06:33	SEVERE	exportuvfits::::casa	Task exportuvfits raised an exception of class RuntimeError with the following message: Exception: Error in output file : File /Users/Ridhima/Softwares/anaconda3/lib/python3.6/site-packages/dfilter_imaging-1.1.0-py3.6.egg/dfilter_imaging/data/zen.2458114.31193.HH.xx.t0.uvfits exists, and the user does not want to remove it..
2021-03-15 11:06:33	SEVERE	exportuvfits::::casa+	... thrown by void casa6core::MSFitsOutput::write() const at File: casacore/msfits/MSFits/MSFitsOutput.cc, line: 173
2021-03-15 11:06:33	INFO	exportuvfits::::casa	Task exportuvfits complete. Start time: 2021-03-15 16:06:33.079308 End time: 2021-03-15 16:06:33.103808
2021-03-15 11:06:33	INFO	exportuvfits::::casa	##### End Task: exportuvfits         #####
2021-03-15 11:06:33	INFO	exportuvfits::::casa	##########################################
2021-03-15 11:06:33	WARN	putcol::MODEL_DATA	No table specified, please open first
2021-03-15 11:06:33	INFO	name::	No table opened.
2021-03-15 11:06:33	SEVERE	getcol::MODEL_DATA	Exception Reported: TableProxy::getColumn: column MODEL_DATA does not exist
